Internal Server Error: /
Traceback (most recent call last):
  File "/home/master/.local/lib64/python3.6/site-packages/django/db/backends/utils.py", line 84, in _execute
    return self.cursor.execute(sql, params)
  File "/home/master/.local/lib64/python3.6/site-packages/django/db/backends/sqlite3/base.py", line 383, in execute
    return Database.Cursor.execute(self, query, params)
sqlite3.IntegrityError: NOT NULL constraint failed: index_post.author_id

The above exception was the direct cause of the following exception:

Traceback (most recent call last):
  File "/home/master/.local/lib64/python3.6/site-packages/django/core/handlers/exception.py", line 34, in inner
    response = get_response(request)
  File "/home/master/.local/lib64/python3.6/site-packages/django/core/handlers/base.py", line 115, in _get_response
    response = self.process_exception_by_middleware(e, request)
  File "/home/master/.local/lib64/python3.6/site-packages/django/core/handlers/base.py", line 113, in _get_response
    response = wrapped_callback(request, *callback_args, **callback_kwargs)
  File "/home/master/PycharmProjects/blog/index/views.py", line 17, in home
    post = Post.objects.create()
  File "/home/master/.local/lib64/python3.6/site-packages/django/db/models/manager.py", line 82, in manager_method
    return getattr(self.get_queryset(), name)(*args, **kwargs)
  File "/home/master/.local/lib64/python3.6/site-packages/django/db/models/query.py", line 422, in create
    obj.save(force_insert=True, using=self.db)
  File "/home/master/.local/lib64/python3.6/site-packages/django/db/models/base.py", line 741, in save
    force_update=force_update, update_fields=update_fields)
  File "/home/master/.local/lib64/python3.6/site-packages/django/db/models/base.py", line 779, in save_base
    force_update, using, update_fields,
  File "/home/master/.local/lib64/python3.6/site-packages/django/db/models/base.py", line 870, in _save_table
    result = self._do_insert(cls._base_manager, using, fields, update_pk, raw)
  File "/home/master/.local/lib64/python3.6/site-packages/django/db/models/base.py", line 908, in _do_insert
    using=using, raw=raw)
  File "/home/master/.local/lib64/python3.6/site-packages/django/db/models/manager.py", line 82, in manager_method
    return getattr(self.get_queryset(), name)(*args, **kwargs)
  File "/home/master/.local/lib64/python3.6/site-packages/django/db/models/query.py", line 1186, in _insert
    return query.get_compiler(using=using).execute_sql(return_id)
  File "/home/master/.local/lib64/python3.6/site-packages/django/db/models/sql/compiler.py", line 1335, in execute_sql
    cursor.execute(sql, params)
  File "/home/master/.local/lib64/python3.6/site-packages/django/db/backends/utils.py", line 99, in execute
    return super().execute(sql, params)
  File "/home/master/.local/lib64/python3.6/site-packages/django/db/backends/utils.py", line 67, in execute
    return self._execute_with_wrappers(sql, params, many=False, executor=self._execute)
  File "/home/master/.local/lib64/python3.6/site-packages/django/db/backends/utils.py", line 76, in _execute_with_wrappers
    return executor(sql, params, many, context)
  File "/home/master/.local/lib64/python3.6/site-packages/django/db/backends/utils.py", line 84, in _execute
    return self.cursor.execute(sql, params)
  File "/home/master/.local/lib64/python3.6/site-packages/django/db/utils.py", line 89, in __exit__
    raise dj_exc_value.with_traceback(traceback) from exc_value
  File "/home/master/.local/lib64/python3.6/site-packages/django/db/backends/utils.py", line 84, in _execute
    return self.cursor.execute(sql, params)
  File "/home/master/.local/lib64/python3.6/site-packages/django/db/backends/sqlite3/base.py", line 383, in execute
    return Database.Cursor.execute(self, query, params)
django.db.utils.IntegrityError: NOT NULL constraint failed: index_post.author_id
"GET / HTTP/1.1" 500 160661
Internal Server Error: /
Traceback (most recent call last):
  File "/home/master/.local/lib64/python3.6/site-packages/django/db/backends/utils.py", line 84, in _execute
    return self.cursor.execute(sql, params)
  File "/home/master/.local/lib64/python3.6/site-packages/django/db/backends/sqlite3/base.py", line 383, in execute
    return Database.Cursor.execute(self, query, params)
sqlite3.IntegrityError: NOT NULL constraint failed: index_post.author_id

The above exception was the direct cause of the following exception:

Traceback (most recent call last):
  File "/home/master/.local/lib64/python3.6/site-packages/django/core/handlers/exception.py", line 34, in inner
    response = get_response(request)
  File "/home/master/.local/lib64/python3.6/site-packages/django/core/handlers/base.py", line 115, in _get_response
    response = self.process_exception_by_middleware(e, request)
  File "/home/master/.local/lib64/python3.6/site-packages/django/core/handlers/base.py", line 113, in _get_response
    response = wrapped_callback(request, *callback_args, **callback_kwargs)
  File "/home/master/PycharmProjects/blog/index/views.py", line 17, in home
    post = Post.objects.create()
  File "/home/master/.local/lib64/python3.6/site-packages/django/db/models/manager.py", line 82, in manager_method
    return getattr(self.get_queryset(), name)(*args, **kwargs)
  File "/home/master/.local/lib64/python3.6/site-packages/django/db/models/query.py", line 422, in create
    obj.save(force_insert=True, using=self.db)
  File "/home/master/.local/lib64/python3.6/site-packages/django/db/models/base.py", line 741, in save
    force_update=force_update, update_fields=update_fields)
  File "/home/master/.local/lib64/python3.6/site-packages/django/db/models/base.py", line 779, in save_base
    force_update, using, update_fields,
  File "/home/master/.local/lib64/python3.6/site-packages/django/db/models/base.py", line 870, in _save_table
    result = self._do_insert(cls._base_manager, using, fields, update_pk, raw)
  File "/home/master/.local/lib64/python3.6/site-packages/django/db/models/base.py", line 908, in _do_insert
    using=using, raw=raw)
  File "/home/master/.local/lib64/python3.6/site-packages/django/db/models/manager.py", line 82, in manager_method
    return getattr(self.get_queryset(), name)(*args, **kwargs)
  File "/home/master/.local/lib64/python3.6/site-packages/django/db/models/query.py", line 1186, in _insert
    return query.get_compiler(using=using).execute_sql(return_id)
  File "/home/master/.local/lib64/python3.6/site-packages/django/db/models/sql/compiler.py", line 1335, in execute_sql
    cursor.execute(sql, params)
  File "/home/master/.local/lib64/python3.6/site-packages/django/db/backends/utils.py", line 99, in execute
    return super().execute(sql, params)
  File "/home/master/.local/lib64/python3.6/site-packages/django/db/backends/utils.py", line 67, in execute
    return self._execute_with_wrappers(sql, params, many=False, executor=self._execute)
  File "/home/master/.local/lib64/python3.6/site-packages/django/db/backends/utils.py", line 76, in _execute_with_wrappers
    return executor(sql, params, many, context)
  File "/home/master/.local/lib64/python3.6/site-packages/django/db/backends/utils.py", line 84, in _execute
    return self.cursor.execute(sql, params)
  File "/home/master/.local/lib64/python3.6/site-packages/django/db/utils.py", line 89, in __exit__
    raise dj_exc_value.with_traceback(traceback) from exc_value
  File "/home/master/.local/lib64/python3.6/site-packages/django/db/backends/utils.py", line 84, in _execute
    return self.cursor.execute(sql, params)
  File "/home/master/.local/lib64/python3.6/site-packages/django/db/backends/sqlite3/base.py", line 383, in execute
    return Database.Cursor.execute(self, query, params)
django.db.utils.IntegrityError: NOT NULL constraint failed: index_post.author_id
"GET / HTTP/1.1" 500 160632
Internal Server Error: /
Traceback (most recent call last):
  File "/home/master/.local/lib64/python3.6/site-packages/django/core/handlers/exception.py", line 34, in inner
    response = get_response(request)
  File "/home/master/.local/lib64/python3.6/site-packages/django/core/handlers/base.py", line 115, in _get_response
    response = self.process_exception_by_middleware(e, request)
  File "/home/master/.local/lib64/python3.6/site-packages/django/core/handlers/base.py", line 113, in _get_response
    response = wrapped_callback(request, *callback_args, **callback_kwargs)
  File "/home/master/PycharmProjects/blog/index/views.py", line 17, in home
    post = Post.objects.create(author_id=User)
  File "/home/master/.local/lib64/python3.6/site-packages/django/db/models/manager.py", line 82, in manager_method
    return getattr(self.get_queryset(), name)(*args, **kwargs)
  File "/home/master/.local/lib64/python3.6/site-packages/django/db/models/query.py", line 422, in create
    obj.save(force_insert=True, using=self.db)
  File "/home/master/.local/lib64/python3.6/site-packages/django/db/models/base.py", line 741, in save
    force_update=force_update, update_fields=update_fields)
  File "/home/master/.local/lib64/python3.6/site-packages/django/db/models/base.py", line 779, in save_base
    force_update, using, update_fields,
  File "/home/master/.local/lib64/python3.6/site-packages/django/db/models/base.py", line 870, in _save_table
    result = self._do_insert(cls._base_manager, using, fields, update_pk, raw)
  File "/home/master/.local/lib64/python3.6/site-packages/django/db/models/base.py", line 908, in _do_insert
    using=using, raw=raw)
  File "/home/master/.local/lib64/python3.6/site-packages/django/db/models/manager.py", line 82, in manager_method
    return getattr(self.get_queryset(), name)(*args, **kwargs)
  File "/home/master/.local/lib64/python3.6/site-packages/django/db/models/query.py", line 1186, in _insert
    return query.get_compiler(using=using).execute_sql(return_id)
  File "/home/master/.local/lib64/python3.6/site-packages/django/db/models/sql/compiler.py", line 1334, in execute_sql
    for sql, params in self.as_sql():
  File "/home/master/.local/lib64/python3.6/site-packages/django/db/models/sql/compiler.py", line 1278, in as_sql
    for obj in self.query.objs
  File "/home/master/.local/lib64/python3.6/site-packages/django/db/models/sql/compiler.py", line 1278, in <listcomp>
    for obj in self.query.objs
  File "/home/master/.local/lib64/python3.6/site-packages/django/db/models/sql/compiler.py", line 1277, in <listcomp>
    [self.prepare_value(field, self.pre_save_val(field, obj)) for field in fields]
  File "/home/master/.local/lib64/python3.6/site-packages/django/db/models/sql/compiler.py", line 1218, in prepare_value
    value = field.get_db_prep_save(value, connection=self.connection)
  File "/home/master/.local/lib64/python3.6/site-packages/django/db/models/fields/related.py", line 937, in get_db_prep_save
    return self.target_field.get_db_prep_save(value, connection=connection)
  File "/home/master/.local/lib64/python3.6/site-packages/django/db/models/fields/__init__.py", line 789, in get_db_prep_save
    return self.get_db_prep_value(value, connection=connection, prepared=False)
  File "/home/master/.local/lib64/python3.6/site-packages/django/db/models/fields/__init__.py", line 957, in get_db_prep_value
    value = self.get_prep_value(value)
  File "/home/master/.local/lib64/python3.6/site-packages/django/db/models/fields/__init__.py", line 966, in get_prep_value
    return int(value)
TypeError: int() argument must be a string, a bytes-like object or a number, not 'ModelBase'
"GET / HTTP/1.1" 500 152697
Internal Server Error: /
Traceback (most recent call last):
  File "/home/master/.local/lib64/python3.6/site-packages/django/db/backends/utils.py", line 84, in _execute
    return self.cursor.execute(sql, params)
  File "/home/master/.local/lib64/python3.6/site-packages/django/db/backends/sqlite3/base.py", line 383, in execute
    return Database.Cursor.execute(self, query, params)
sqlite3.IntegrityError: FOREIGN KEY constraint failed

The above exception was the direct cause of the following exception:

Traceback (most recent call last):
  File "/home/master/.local/lib64/python3.6/site-packages/django/core/handlers/exception.py", line 34, in inner
    response = get_response(request)
  File "/home/master/.local/lib64/python3.6/site-packages/django/core/handlers/base.py", line 115, in _get_response
    response = self.process_exception_by_middleware(e, request)
  File "/home/master/.local/lib64/python3.6/site-packages/django/core/handlers/base.py", line 113, in _get_response
    response = wrapped_callback(request, *callback_args, **callback_kwargs)
  File "/home/master/PycharmProjects/blog/index/views.py", line 17, in home
    post = Post.objects.create(author_id=100)
  File "/home/master/.local/lib64/python3.6/site-packages/django/db/models/manager.py", line 82, in manager_method
    return getattr(self.get_queryset(), name)(*args, **kwargs)
  File "/home/master/.local/lib64/python3.6/site-packages/django/db/models/query.py", line 422, in create
    obj.save(force_insert=True, using=self.db)
  File "/home/master/.local/lib64/python3.6/site-packages/django/db/models/base.py", line 741, in save
    force_update=force_update, update_fields=update_fields)
  File "/home/master/.local/lib64/python3.6/site-packages/django/db/models/base.py", line 779, in save_base
    force_update, using, update_fields,
  File "/home/master/.local/lib64/python3.6/site-packages/django/db/models/base.py", line 870, in _save_table
    result = self._do_insert(cls._base_manager, using, fields, update_pk, raw)
  File "/home/master/.local/lib64/python3.6/site-packages/django/db/models/base.py", line 908, in _do_insert
    using=using, raw=raw)
  File "/home/master/.local/lib64/python3.6/site-packages/django/db/models/manager.py", line 82, in manager_method
    return getattr(self.get_queryset(), name)(*args, **kwargs)
  File "/home/master/.local/lib64/python3.6/site-packages/django/db/models/query.py", line 1186, in _insert
    return query.get_compiler(using=using).execute_sql(return_id)
  File "/home/master/.local/lib64/python3.6/site-packages/django/db/models/sql/compiler.py", line 1335, in execute_sql
    cursor.execute(sql, params)
  File "/home/master/.local/lib64/python3.6/site-packages/django/db/backends/utils.py", line 99, in execute
    return super().execute(sql, params)
  File "/home/master/.local/lib64/python3.6/site-packages/django/db/backends/utils.py", line 67, in execute
    return self._execute_with_wrappers(sql, params, many=False, executor=self._execute)
  File "/home/master/.local/lib64/python3.6/site-packages/django/db/backends/utils.py", line 76, in _execute_with_wrappers
    return executor(sql, params, many, context)
  File "/home/master/.local/lib64/python3.6/site-packages/django/db/backends/utils.py", line 84, in _execute
    return self.cursor.execute(sql, params)
  File "/home/master/.local/lib64/python3.6/site-packages/django/db/utils.py", line 89, in __exit__
    raise dj_exc_value.with_traceback(traceback) from exc_value
  File "/home/master/.local/lib64/python3.6/site-packages/django/db/backends/utils.py", line 84, in _execute
    return self.cursor.execute(sql, params)
  File "/home/master/.local/lib64/python3.6/site-packages/django/db/backends/sqlite3/base.py", line 383, in execute
    return Database.Cursor.execute(self, query, params)
django.db.utils.IntegrityError: FOREIGN KEY constraint failed
"GET / HTTP/1.1" 500 160544
Internal Server Error: /
Traceback (most recent call last):
  File "/home/master/.local/lib64/python3.6/site-packages/django/core/handlers/exception.py", line 34, in inner
    response = get_response(request)
  File "/home/master/.local/lib64/python3.6/site-packages/django/core/handlers/base.py", line 115, in _get_response
    response = self.process_exception_by_middleware(e, request)
  File "/home/master/.local/lib64/python3.6/site-packages/django/core/handlers/base.py", line 113, in _get_response
    response = wrapped_callback(request, *callback_args, **callback_kwargs)
  File "/home/master/PycharmProjects/blog/index/views.py", line 18, in home
    post.author = 'master'
  File "/home/master/.local/lib64/python3.6/site-packages/django/db/models/fields/related_descriptors.py", line 211, in __set__
    self.field.remote_field.model._meta.object_name,
ValueError: Cannot assign "'master'": "Post.author" must be a "User" instance.
"GET / HTTP/1.1" 500 75505
Internal Server Error: /
Traceback (most recent call last):
  File "/home/master/.local/lib64/python3.6/site-packages/django/core/handlers/exception.py", line 34, in inner
    response = get_response(request)
  File "/home/master/.local/lib64/python3.6/site-packages/django/core/handlers/base.py", line 115, in _get_response
    response = self.process_exception_by_middleware(e, request)
  File "/home/master/.local/lib64/python3.6/site-packages/django/core/handlers/base.py", line 113, in _get_response
    response = wrapped_callback(request, *callback_args, **callback_kwargs)
  File "/home/master/PycharmProjects/blog/index/views.py", line 17, in home
    post = Post.objects.create(author_id=User.get_full_name())
TypeError: get_full_name() missing 1 required positional argument: 'self'
"GET / HTTP/1.1" 500 70760
Internal Server Error: /
Traceback (most recent call last):
  File "/home/master/.local/lib64/python3.6/site-packages/django/core/handlers/exception.py", line 34, in inner
    response = get_response(request)
  File "/home/master/.local/lib64/python3.6/site-packages/django/core/handlers/base.py", line 115, in _get_response
    response = self.process_exception_by_middleware(e, request)
  File "/home/master/.local/lib64/python3.6/site-packages/django/core/handlers/base.py", line 113, in _get_response
    response = wrapped_callback(request, *callback_args, **callback_kwargs)
  File "/home/master/PycharmProjects/blog/index/views.py", line 17, in home
    post = Post.objects.create(author_id=User.objects.get(id(0)))
  File "/home/master/.local/lib64/python3.6/site-packages/django/db/models/manager.py", line 82, in manager_method
    return getattr(self.get_queryset(), name)(*args, **kwargs)
  File "/home/master/.local/lib64/python3.6/site-packages/django/db/models/query.py", line 399, in get
    clone = self.filter(*args, **kwargs)
  File "/home/master/.local/lib64/python3.6/site-packages/django/db/models/query.py", line 892, in filter
    return self._filter_or_exclude(False, *args, **kwargs)
  File "/home/master/.local/lib64/python3.6/site-packages/django/db/models/query.py", line 910, in _filter_or_exclude
    clone.query.add_q(Q(*args, **kwargs))
  File "/home/master/.local/lib64/python3.6/site-packages/django/db/models/sql/query.py", line 1290, in add_q
    clause, _ = self._add_q(q_object, self.used_aliases)
  File "/home/master/.local/lib64/python3.6/site-packages/django/db/models/sql/query.py", line 1318, in _add_q
    split_subq=split_subq, simple_col=simple_col,
  File "/home/master/.local/lib64/python3.6/site-packages/django/db/models/sql/query.py", line 1187, in build_filter
    arg, value = filter_expr
TypeError: 'int' object is not iterable
"GET / HTTP/1.1" 500 102827
Internal Server Error: /
Traceback (most recent call last):
  File "/home/master/.local/lib64/python3.6/site-packages/django/core/handlers/exception.py", line 34, in inner
    response = get_response(request)
  File "/home/master/.local/lib64/python3.6/site-packages/django/core/handlers/base.py", line 115, in _get_response
    response = self.process_exception_by_middleware(e, request)
  File "/home/master/.local/lib64/python3.6/site-packages/django/core/handlers/base.py", line 113, in _get_response
    response = wrapped_callback(request, *callback_args, **callback_kwargs)
  File "/home/master/PycharmProjects/blog/index/views.py", line 17, in home
    post = Post.objects.create(author_id=User.objects.get())
  File "/home/master/.local/lib64/python3.6/site-packages/django/db/models/manager.py", line 82, in manager_method
    return getattr(self.get_queryset(), name)(*args, **kwargs)
  File "/home/master/.local/lib64/python3.6/site-packages/django/db/models/query.py", line 412, in get
    (self.model._meta.object_name, num)
django.contrib.auth.models.User.MultipleObjectsReturned: get() returned more than one User -- it returned 2!
"GET / HTTP/1.1" 500 79463
Internal Server Error: /
Traceback (most recent call last):
  File "/home/master/.local/lib64/python3.6/site-packages/django/core/handlers/exception.py", line 34, in inner
    response = get_response(request)
  File "/home/master/.local/lib64/python3.6/site-packages/django/core/handlers/base.py", line 115, in _get_response
    response = self.process_exception_by_middleware(e, request)
  File "/home/master/.local/lib64/python3.6/site-packages/django/core/handlers/base.py", line 113, in _get_response
    response = wrapped_callback(request, *callback_args, **callback_kwargs)
  File "/home/master/PycharmProjects/blog/index/views.py", line 17, in home
    post = Post.objects.create(author_id=User.objects.get.first())
AttributeError: 'function' object has no attribute 'first'
"GET / HTTP/1.1" 500 70750
Internal Server Error: /
Traceback (most recent call last):
  File "/home/master/.local/lib64/python3.6/site-packages/django/core/handlers/exception.py", line 34, in inner
    response = get_response(request)
  File "/home/master/.local/lib64/python3.6/site-packages/django/core/handlers/base.py", line 115, in _get_response
    response = self.process_exception_by_middleware(e, request)
  File "/home/master/.local/lib64/python3.6/site-packages/django/core/handlers/base.py", line 113, in _get_response
    response = wrapped_callback(request, *callback_args, **callback_kwargs)
  File "/home/master/PycharmProjects/blog/index/views.py", line 17, in home
    post = Post.objects.create(author_id=User.objects.first())
  File "/home/master/.local/lib64/python3.6/site-packages/django/db/models/manager.py", line 82, in manager_method
    return getattr(self.get_queryset(), name)(*args, **kwargs)
  File "/home/master/.local/lib64/python3.6/site-packages/django/db/models/query.py", line 422, in create
    obj.save(force_insert=True, using=self.db)
  File "/home/master/.local/lib64/python3.6/site-packages/django/db/models/base.py", line 741, in save
    force_update=force_update, update_fields=update_fields)
  File "/home/master/.local/lib64/python3.6/site-packages/django/db/models/base.py", line 779, in save_base
    force_update, using, update_fields,
  File "/home/master/.local/lib64/python3.6/site-packages/django/db/models/base.py", line 870, in _save_table
    result = self._do_insert(cls._base_manager, using, fields, update_pk, raw)
  File "/home/master/.local/lib64/python3.6/site-packages/django/db/models/base.py", line 908, in _do_insert
    using=using, raw=raw)
  File "/home/master/.local/lib64/python3.6/site-packages/django/db/models/manager.py", line 82, in manager_method
    return getattr(self.get_queryset(), name)(*args, **kwargs)
  File "/home/master/.local/lib64/python3.6/site-packages/django/db/models/query.py", line 1186, in _insert
    return query.get_compiler(using=using).execute_sql(return_id)
  File "/home/master/.local/lib64/python3.6/site-packages/django/db/models/sql/compiler.py", line 1334, in execute_sql
    for sql, params in self.as_sql():
  File "/home/master/.local/lib64/python3.6/site-packages/django/db/models/sql/compiler.py", line 1278, in as_sql
    for obj in self.query.objs
  File "/home/master/.local/lib64/python3.6/site-packages/django/db/models/sql/compiler.py", line 1278, in <listcomp>
    for obj in self.query.objs
  File "/home/master/.local/lib64/python3.6/site-packages/django/db/models/sql/compiler.py", line 1277, in <listcomp>
    [self.prepare_value(field, self.pre_save_val(field, obj)) for field in fields]
  File "/home/master/.local/lib64/python3.6/site-packages/django/db/models/sql/compiler.py", line 1218, in prepare_value
    value = field.get_db_prep_save(value, connection=self.connection)
  File "/home/master/.local/lib64/python3.6/site-packages/django/db/models/fields/related.py", line 937, in get_db_prep_save
    return self.target_field.get_db_prep_save(value, connection=connection)
  File "/home/master/.local/lib64/python3.6/site-packages/django/db/models/fields/__init__.py", line 789, in get_db_prep_save
    return self.get_db_prep_value(value, connection=connection, prepared=False)
  File "/home/master/.local/lib64/python3.6/site-packages/django/db/models/fields/__init__.py", line 957, in get_db_prep_value
    value = self.get_prep_value(value)
  File "/home/master/.local/lib64/python3.6/site-packages/django/db/models/fields/__init__.py", line 966, in get_prep_value
    return int(value)
TypeError: int() argument must be a string, a bytes-like object or a number, not 'User'
"GET / HTTP/1.1" 500 152512
Internal Server Error: /
Traceback (most recent call last):
  File "/home/master/.local/lib64/python3.6/site-packages/django/db/backends/utils.py", line 84, in _execute
    return self.cursor.execute(sql, params)
  File "/home/master/.local/lib64/python3.6/site-packages/django/db/backends/sqlite3/base.py", line 383, in execute
    return Database.Cursor.execute(self, query, params)
sqlite3.IntegrityError: NOT NULL constraint failed: index_post.author_id

The above exception was the direct cause of the following exception:

Traceback (most recent call last):
  File "/home/master/.local/lib64/python3.6/site-packages/django/core/handlers/exception.py", line 34, in inner
    response = get_response(request)
  File "/home/master/.local/lib64/python3.6/site-packages/django/core/handlers/base.py", line 115, in _get_response
    response = self.process_exception_by_middleware(e, request)
  File "/home/master/.local/lib64/python3.6/site-packages/django/core/handlers/base.py", line 113, in _get_response
    response = wrapped_callback(request, *callback_args, **callback_kwargs)
  File "/home/master/PycharmProjects/blog/index/views.py", line 17, in home
    post = Post.objects.create(author_id=request.user.id)
  File "/home/master/.local/lib64/python3.6/site-packages/django/db/models/manager.py", line 82, in manager_method
    return getattr(self.get_queryset(), name)(*args, **kwargs)
  File "/home/master/.local/lib64/python3.6/site-packages/django/db/models/query.py", line 422, in create
    obj.save(force_insert=True, using=self.db)
  File "/home/master/.local/lib64/python3.6/site-packages/django/db/models/base.py", line 741, in save
    force_update=force_update, update_fields=update_fields)
  File "/home/master/.local/lib64/python3.6/site-packages/django/db/models/base.py", line 779, in save_base
    force_update, using, update_fields,
  File "/home/master/.local/lib64/python3.6/site-packages/django/db/models/base.py", line 870, in _save_table
    result = self._do_insert(cls._base_manager, using, fields, update_pk, raw)
  File "/home/master/.local/lib64/python3.6/site-packages/django/db/models/base.py", line 908, in _do_insert
    using=using, raw=raw)
  File "/home/master/.local/lib64/python3.6/site-packages/django/db/models/manager.py", line 82, in manager_method
    return getattr(self.get_queryset(), name)(*args, **kwargs)
  File "/home/master/.local/lib64/python3.6/site-packages/django/db/models/query.py", line 1186, in _insert
    return query.get_compiler(using=using).execute_sql(return_id)
  File "/home/master/.local/lib64/python3.6/site-packages/django/db/models/sql/compiler.py", line 1335, in execute_sql
    cursor.execute(sql, params)
  File "/home/master/.local/lib64/python3.6/site-packages/django/db/backends/utils.py", line 99, in execute
    return super().execute(sql, params)
  File "/home/master/.local/lib64/python3.6/site-packages/django/db/backends/utils.py", line 67, in execute
    return self._execute_with_wrappers(sql, params, many=False, executor=self._execute)
  File "/home/master/.local/lib64/python3.6/site-packages/django/db/backends/utils.py", line 76, in _execute_with_wrappers
    return executor(sql, params, many, context)
  File "/home/master/.local/lib64/python3.6/site-packages/django/db/backends/utils.py", line 84, in _execute
    return self.cursor.execute(sql, params)
  File "/home/master/.local/lib64/python3.6/site-packages/django/db/utils.py", line 89, in __exit__
    raise dj_exc_value.with_traceback(traceback) from exc_value
  File "/home/master/.local/lib64/python3.6/site-packages/django/db/backends/utils.py", line 84, in _execute
    return self.cursor.execute(sql, params)
  File "/home/master/.local/lib64/python3.6/site-packages/django/db/backends/sqlite3/base.py", line 383, in execute
    return Database.Cursor.execute(self, query, params)
django.db.utils.IntegrityError: NOT NULL constraint failed: index_post.author_id
"GET / HTTP/1.1" 500 160780
Internal Server Error: /
Traceback (most recent call last):
  File "/home/master/.local/lib64/python3.6/site-packages/django/db/backends/utils.py", line 84, in _execute
    return self.cursor.execute(sql, params)
  File "/home/master/.local/lib64/python3.6/site-packages/django/db/backends/sqlite3/base.py", line 383, in execute
    return Database.Cursor.execute(self, query, params)
sqlite3.IntegrityError: NOT NULL constraint failed: index_post.author_id

The above exception was the direct cause of the following exception:

Traceback (most recent call last):
  File "/home/master/.local/lib64/python3.6/site-packages/django/core/handlers/exception.py", line 34, in inner
    response = get_response(request)
  File "/home/master/.local/lib64/python3.6/site-packages/django/core/handlers/base.py", line 115, in _get_response
    response = self.process_exception_by_middleware(e, request)
  File "/home/master/.local/lib64/python3.6/site-packages/django/core/handlers/base.py", line 113, in _get_response
    response = wrapped_callback(request, *callback_args, **callback_kwargs)
  File "/home/master/PycharmProjects/blog/index/views.py", line 17, in home
    post = Post.objects.create()
  File "/home/master/.local/lib64/python3.6/site-packages/django/db/models/manager.py", line 82, in manager_method
    return getattr(self.get_queryset(), name)(*args, **kwargs)
  File "/home/master/.local/lib64/python3.6/site-packages/django/db/models/query.py", line 422, in create
    obj.save(force_insert=True, using=self.db)
  File "/home/master/.local/lib64/python3.6/site-packages/django/db/models/base.py", line 741, in save
    force_update=force_update, update_fields=update_fields)
  File "/home/master/.local/lib64/python3.6/site-packages/django/db/models/base.py", line 779, in save_base
    force_update, using, update_fields,
  File "/home/master/.local/lib64/python3.6/site-packages/django/db/models/base.py", line 870, in _save_table
    result = self._do_insert(cls._base_manager, using, fields, update_pk, raw)
  File "/home/master/.local/lib64/python3.6/site-packages/django/db/models/base.py", line 908, in _do_insert
    using=using, raw=raw)
  File "/home/master/.local/lib64/python3.6/site-packages/django/db/models/manager.py", line 82, in manager_method
    return getattr(self.get_queryset(), name)(*args, **kwargs)
  File "/home/master/.local/lib64/python3.6/site-packages/django/db/models/query.py", line 1186, in _insert
    return query.get_compiler(using=using).execute_sql(return_id)
  File "/home/master/.local/lib64/python3.6/site-packages/django/db/models/sql/compiler.py", line 1335, in execute_sql
    cursor.execute(sql, params)
  File "/home/master/.local/lib64/python3.6/site-packages/django/db/backends/utils.py", line 99, in execute
    return super().execute(sql, params)
  File "/home/master/.local/lib64/python3.6/site-packages/django/db/backends/utils.py", line 67, in execute
    return self._execute_with_wrappers(sql, params, many=False, executor=self._execute)
  File "/home/master/.local/lib64/python3.6/site-packages/django/db/backends/utils.py", line 76, in _execute_with_wrappers
    return executor(sql, params, many, context)
  File "/home/master/.local/lib64/python3.6/site-packages/django/db/backends/utils.py", line 84, in _execute
    return self.cursor.execute(sql, params)
  File "/home/master/.local/lib64/python3.6/site-packages/django/db/utils.py", line 89, in __exit__
    raise dj_exc_value.with_traceback(traceback) from exc_value
  File "/home/master/.local/lib64/python3.6/site-packages/django/db/backends/utils.py", line 84, in _execute
    return self.cursor.execute(sql, params)
  File "/home/master/.local/lib64/python3.6/site-packages/django/db/backends/sqlite3/base.py", line 383, in execute
    return Database.Cursor.execute(self, query, params)
django.db.utils.IntegrityError: NOT NULL constraint failed: index_post.author_id
"GET / HTTP/1.1" 500 160714
Internal Server Error: /
Traceback (most recent call last):
  File "/home/master/.local/lib64/python3.6/site-packages/django/db/backends/utils.py", line 84, in _execute
    return self.cursor.execute(sql, params)
  File "/home/master/.local/lib64/python3.6/site-packages/django/db/backends/sqlite3/base.py", line 383, in execute
    return Database.Cursor.execute(self, query, params)
sqlite3.IntegrityError: NOT NULL constraint failed: index_post.author_id

The above exception was the direct cause of the following exception:

Traceback (most recent call last):
  File "/home/master/.local/lib64/python3.6/site-packages/django/core/handlers/exception.py", line 34, in inner
    response = get_response(request)
  File "/home/master/.local/lib64/python3.6/site-packages/django/core/handlers/base.py", line 115, in _get_response
    response = self.process_exception_by_middleware(e, request)
  File "/home/master/.local/lib64/python3.6/site-packages/django/core/handlers/base.py", line 113, in _get_response
    response = wrapped_callback(request, *callback_args, **callback_kwargs)
  File "/home/master/PycharmProjects/blog/index/views.py", line 17, in home
    post = Post.objects.create()
  File "/home/master/.local/lib64/python3.6/site-packages/django/db/models/manager.py", line 82, in manager_method
    return getattr(self.get_queryset(), name)(*args, **kwargs)
  File "/home/master/.local/lib64/python3.6/site-packages/django/db/models/query.py", line 422, in create
    obj.save(force_insert=True, using=self.db)
  File "/home/master/.local/lib64/python3.6/site-packages/django/db/models/base.py", line 741, in save
    force_update=force_update, update_fields=update_fields)
  File "/home/master/.local/lib64/python3.6/site-packages/django/db/models/base.py", line 779, in save_base
    force_update, using, update_fields,
  File "/home/master/.local/lib64/python3.6/site-packages/django/db/models/base.py", line 870, in _save_table
    result = self._do_insert(cls._base_manager, using, fields, update_pk, raw)
  File "/home/master/.local/lib64/python3.6/site-packages/django/db/models/base.py", line 908, in _do_insert
    using=using, raw=raw)
  File "/home/master/.local/lib64/python3.6/site-packages/django/db/models/manager.py", line 82, in manager_method
    return getattr(self.get_queryset(), name)(*args, **kwargs)
  File "/home/master/.local/lib64/python3.6/site-packages/django/db/models/query.py", line 1186, in _insert
    return query.get_compiler(using=using).execute_sql(return_id)
  File "/home/master/.local/lib64/python3.6/site-packages/django/db/models/sql/compiler.py", line 1335, in execute_sql
    cursor.execute(sql, params)
  File "/home/master/.local/lib64/python3.6/site-packages/django/db/backends/utils.py", line 99, in execute
    return super().execute(sql, params)
  File "/home/master/.local/lib64/python3.6/site-packages/django/db/backends/utils.py", line 67, in execute
    return self._execute_with_wrappers(sql, params, many=False, executor=self._execute)
  File "/home/master/.local/lib64/python3.6/site-packages/django/db/backends/utils.py", line 76, in _execute_with_wrappers
    return executor(sql, params, many, context)
  File "/home/master/.local/lib64/python3.6/site-packages/django/db/backends/utils.py", line 84, in _execute
    return self.cursor.execute(sql, params)
  File "/home/master/.local/lib64/python3.6/site-packages/django/db/utils.py", line 89, in __exit__
    raise dj_exc_value.with_traceback(traceback) from exc_value
  File "/home/master/.local/lib64/python3.6/site-packages/django/db/backends/utils.py", line 84, in _execute
    return self.cursor.execute(sql, params)
  File "/home/master/.local/lib64/python3.6/site-packages/django/db/backends/sqlite3/base.py", line 383, in execute
    return Database.Cursor.execute(self, query, params)
django.db.utils.IntegrityError: NOT NULL constraint failed: index_post.author_id
"GET / HTTP/1.1" 500 160701
Internal Server Error: /
Traceback (most recent call last):
  File "/home/master/.local/lib64/python3.6/site-packages/django/db/backends/utils.py", line 84, in _execute
    return self.cursor.execute(sql, params)
  File "/home/master/.local/lib64/python3.6/site-packages/django/db/backends/sqlite3/base.py", line 383, in execute
    return Database.Cursor.execute(self, query, params)
sqlite3.IntegrityError: NOT NULL constraint failed: index_post.author_id

The above exception was the direct cause of the following exception:

Traceback (most recent call last):
  File "/home/master/.local/lib64/python3.6/site-packages/django/core/handlers/exception.py", line 34, in inner
    response = get_response(request)
  File "/home/master/.local/lib64/python3.6/site-packages/django/core/handlers/base.py", line 115, in _get_response
    response = self.process_exception_by_middleware(e, request)
  File "/home/master/.local/lib64/python3.6/site-packages/django/core/handlers/base.py", line 113, in _get_response
    response = wrapped_callback(request, *callback_args, **callback_kwargs)
  File "/home/master/PycharmProjects/blog/index/views.py", line 17, in home
    post = Post.objects.create()
  File "/home/master/.local/lib64/python3.6/site-packages/django/db/models/manager.py", line 82, in manager_method
    return getattr(self.get_queryset(), name)(*args, **kwargs)
  File "/home/master/.local/lib64/python3.6/site-packages/django/db/models/query.py", line 422, in create
    obj.save(force_insert=True, using=self.db)
  File "/home/master/.local/lib64/python3.6/site-packages/django/db/models/base.py", line 741, in save
    force_update=force_update, update_fields=update_fields)
  File "/home/master/.local/lib64/python3.6/site-packages/django/db/models/base.py", line 779, in save_base
    force_update, using, update_fields,
  File "/home/master/.local/lib64/python3.6/site-packages/django/db/models/base.py", line 870, in _save_table
    result = self._do_insert(cls._base_manager, using, fields, update_pk, raw)
  File "/home/master/.local/lib64/python3.6/site-packages/django/db/models/base.py", line 908, in _do_insert
    using=using, raw=raw)
  File "/home/master/.local/lib64/python3.6/site-packages/django/db/models/manager.py", line 82, in manager_method
    return getattr(self.get_queryset(), name)(*args, **kwargs)
  File "/home/master/.local/lib64/python3.6/site-packages/django/db/models/query.py", line 1186, in _insert
    return query.get_compiler(using=using).execute_sql(return_id)
  File "/home/master/.local/lib64/python3.6/site-packages/django/db/models/sql/compiler.py", line 1335, in execute_sql
    cursor.execute(sql, params)
  File "/home/master/.local/lib64/python3.6/site-packages/django/db/backends/utils.py", line 99, in execute
    return super().execute(sql, params)
  File "/home/master/.local/lib64/python3.6/site-packages/django/db/backends/utils.py", line 67, in execute
    return self._execute_with_wrappers(sql, params, many=False, executor=self._execute)
  File "/home/master/.local/lib64/python3.6/site-packages/django/db/backends/utils.py", line 76, in _execute_with_wrappers
    return executor(sql, params, many, context)
  File "/home/master/.local/lib64/python3.6/site-packages/django/db/backends/utils.py", line 84, in _execute
    return self.cursor.execute(sql, params)
  File "/home/master/.local/lib64/python3.6/site-packages/django/db/utils.py", line 89, in __exit__
    raise dj_exc_value.with_traceback(traceback) from exc_value
  File "/home/master/.local/lib64/python3.6/site-packages/django/db/backends/utils.py", line 84, in _execute
    return self.cursor.execute(sql, params)
  File "/home/master/.local/lib64/python3.6/site-packages/django/db/backends/sqlite3/base.py", line 383, in execute
    return Database.Cursor.execute(self, query, params)
django.db.utils.IntegrityError: NOT NULL constraint failed: index_post.author_id
"GET / HTTP/1.1" 500 160957
Internal Server Error: /
Traceback (most recent call last):
  File "/home/master/.local/lib64/python3.6/site-packages/django/db/backends/utils.py", line 84, in _execute
    return self.cursor.execute(sql, params)
  File "/home/master/.local/lib64/python3.6/site-packages/django/db/backends/sqlite3/base.py", line 383, in execute
    return Database.Cursor.execute(self, query, params)
sqlite3.IntegrityError: NOT NULL constraint failed: index_post.author_id

The above exception was the direct cause of the following exception:

Traceback (most recent call last):
  File "/home/master/.local/lib64/python3.6/site-packages/django/core/handlers/exception.py", line 34, in inner
    response = get_response(request)
  File "/home/master/.local/lib64/python3.6/site-packages/django/core/handlers/base.py", line 115, in _get_response
    response = self.process_exception_by_middleware(e, request)
  File "/home/master/.local/lib64/python3.6/site-packages/django/core/handlers/base.py", line 113, in _get_response
    response = wrapped_callback(request, *callback_args, **callback_kwargs)
  File "/home/master/PycharmProjects/blog/index/views.py", line 17, in home
    post = Post.objects.create()
  File "/home/master/.local/lib64/python3.6/site-packages/django/db/models/manager.py", line 82, in manager_method
    return getattr(self.get_queryset(), name)(*args, **kwargs)
  File "/home/master/.local/lib64/python3.6/site-packages/django/db/models/query.py", line 422, in create
    obj.save(force_insert=True, using=self.db)
  File "/home/master/.local/lib64/python3.6/site-packages/django/db/models/base.py", line 741, in save
    force_update=force_update, update_fields=update_fields)
  File "/home/master/.local/lib64/python3.6/site-packages/django/db/models/base.py", line 779, in save_base
    force_update, using, update_fields,
  File "/home/master/.local/lib64/python3.6/site-packages/django/db/models/base.py", line 870, in _save_table
    result = self._do_insert(cls._base_manager, using, fields, update_pk, raw)
  File "/home/master/.local/lib64/python3.6/site-packages/django/db/models/base.py", line 908, in _do_insert
    using=using, raw=raw)
  File "/home/master/.local/lib64/python3.6/site-packages/django/db/models/manager.py", line 82, in manager_method
    return getattr(self.get_queryset(), name)(*args, **kwargs)
  File "/home/master/.local/lib64/python3.6/site-packages/django/db/models/query.py", line 1186, in _insert
    return query.get_compiler(using=using).execute_sql(return_id)
  File "/home/master/.local/lib64/python3.6/site-packages/django/db/models/sql/compiler.py", line 1335, in execute_sql
    cursor.execute(sql, params)
  File "/home/master/.local/lib64/python3.6/site-packages/django/db/backends/utils.py", line 99, in execute
    return super().execute(sql, params)
  File "/home/master/.local/lib64/python3.6/site-packages/django/db/backends/utils.py", line 67, in execute
    return self._execute_with_wrappers(sql, params, many=False, executor=self._execute)
  File "/home/master/.local/lib64/python3.6/site-packages/django/db/backends/utils.py", line 76, in _execute_with_wrappers
    return executor(sql, params, many, context)
  File "/home/master/.local/lib64/python3.6/site-packages/django/db/backends/utils.py", line 84, in _execute
    return self.cursor.execute(sql, params)
  File "/home/master/.local/lib64/python3.6/site-packages/django/db/utils.py", line 89, in __exit__
    raise dj_exc_value.with_traceback(traceback) from exc_value
  File "/home/master/.local/lib64/python3.6/site-packages/django/db/backends/utils.py", line 84, in _execute
    return self.cursor.execute(sql, params)
  File "/home/master/.local/lib64/python3.6/site-packages/django/db/backends/sqlite3/base.py", line 383, in execute
    return Database.Cursor.execute(self, query, params)
django.db.utils.IntegrityError: NOT NULL constraint failed: index_post.author_id
"GET / HTTP/1.1" 500 160945
Internal Server Error: /
Traceback (most recent call last):
  File "/home/master/.local/lib64/python3.6/site-packages/django/db/backends/utils.py", line 84, in _execute
    return self.cursor.execute(sql, params)
  File "/home/master/.local/lib64/python3.6/site-packages/django/db/backends/sqlite3/base.py", line 383, in execute
    return Database.Cursor.execute(self, query, params)
sqlite3.IntegrityError: NOT NULL constraint failed: index_post.author_id

The above exception was the direct cause of the following exception:

Traceback (most recent call last):
  File "/home/master/.local/lib64/python3.6/site-packages/django/core/handlers/exception.py", line 34, in inner
    response = get_response(request)
  File "/home/master/.local/lib64/python3.6/site-packages/django/core/handlers/base.py", line 115, in _get_response
    response = self.process_exception_by_middleware(e, request)
  File "/home/master/.local/lib64/python3.6/site-packages/django/core/handlers/base.py", line 113, in _get_response
    response = wrapped_callback(request, *callback_args, **callback_kwargs)
  File "/home/master/PycharmProjects/blog/index/views.py", line 17, in home
    post = Post.objects.create()
  File "/home/master/.local/lib64/python3.6/site-packages/django/db/models/manager.py", line 82, in manager_method
    return getattr(self.get_queryset(), name)(*args, **kwargs)
  File "/home/master/.local/lib64/python3.6/site-packages/django/db/models/query.py", line 422, in create
    obj.save(force_insert=True, using=self.db)
  File "/home/master/.local/lib64/python3.6/site-packages/django/db/models/base.py", line 741, in save
    force_update=force_update, update_fields=update_fields)
  File "/home/master/.local/lib64/python3.6/site-packages/django/db/models/base.py", line 779, in save_base
    force_update, using, update_fields,
  File "/home/master/.local/lib64/python3.6/site-packages/django/db/models/base.py", line 870, in _save_table
    result = self._do_insert(cls._base_manager, using, fields, update_pk, raw)
  File "/home/master/.local/lib64/python3.6/site-packages/django/db/models/base.py", line 908, in _do_insert
    using=using, raw=raw)
  File "/home/master/.local/lib64/python3.6/site-packages/django/db/models/manager.py", line 82, in manager_method
    return getattr(self.get_queryset(), name)(*args, **kwargs)
  File "/home/master/.local/lib64/python3.6/site-packages/django/db/models/query.py", line 1186, in _insert
    return query.get_compiler(using=using).execute_sql(return_id)
  File "/home/master/.local/lib64/python3.6/site-packages/django/db/models/sql/compiler.py", line 1335, in execute_sql
    cursor.execute(sql, params)
  File "/home/master/.local/lib64/python3.6/site-packages/django/db/backends/utils.py", line 99, in execute
    return super().execute(sql, params)
  File "/home/master/.local/lib64/python3.6/site-packages/django/db/backends/utils.py", line 67, in execute
    return self._execute_with_wrappers(sql, params, many=False, executor=self._execute)
  File "/home/master/.local/lib64/python3.6/site-packages/django/db/backends/utils.py", line 76, in _execute_with_wrappers
    return executor(sql, params, many, context)
  File "/home/master/.local/lib64/python3.6/site-packages/django/db/backends/utils.py", line 84, in _execute
    return self.cursor.execute(sql, params)
  File "/home/master/.local/lib64/python3.6/site-packages/django/db/utils.py", line 89, in __exit__
    raise dj_exc_value.with_traceback(traceback) from exc_value
  File "/home/master/.local/lib64/python3.6/site-packages/django/db/backends/utils.py", line 84, in _execute
    return self.cursor.execute(sql, params)
  File "/home/master/.local/lib64/python3.6/site-packages/django/db/backends/sqlite3/base.py", line 383, in execute
    return Database.Cursor.execute(self, query, params)
django.db.utils.IntegrityError: NOT NULL constraint failed: index_post.author_id
"GET / HTTP/1.1" 500 160945
Watching for file changes with StatReloader
Watching for file changes with StatReloader
"GET / HTTP/1.1" 200 9006
/home/master/PycharmProjects/blog/index/models.py changed, reloading.
Watching for file changes with StatReloader
/home/master/PycharmProjects/blog/index/models.py changed, reloading.
Watching for file changes with StatReloader
/home/master/PycharmProjects/blog/index/models.py changed, reloading.
Watching for file changes with StatReloader
"GET / HTTP/1.1" 200 9006
Watching for file changes with StatReloader
"GET / HTTP/1.1" 200 9006
"GET / HTTP/1.1" 200 9006
/home/master/PycharmProjects/blog/index/models.py changed, reloading.
Watching for file changes with StatReloader
Watching for file changes with StatReloader
"GET / HTTP/1.1" 200 9006
/home/master/PycharmProjects/blog/index/models.py changed, reloading.
Watching for file changes with StatReloader
"GET / HTTP/1.1" 200 9006
Watching for file changes with StatReloader
"GET / HTTP/1.1" 200 9006
Watching for file changes with StatReloader
"GET / HTTP/1.1" 200 9006
Watching for file changes with StatReloader
"GET / HTTP/1.1" 200 9006
"GET /admin/ HTTP/1.1" 302 0
"GET /admin/login/?next=/admin/ HTTP/1.1" 200 1819
"POST /admin/login/?next=/admin/ HTTP/1.1" 302 0
"GET /admin/ HTTP/1.1" 200 7203
"GET /admin/index/post/ HTTP/1.1" 200 5275
"GET /static/admin/css/responsive.css HTTP/1.1" 200 8192
"GET /admin/jsi18n/ HTTP/1.1" 200 3223
"GET /static/admin/css/fonts.css HTTP/1.1" 200 423
"POST /admin/index/post/ HTTP/1.1" 200 3306
"GET /static/admin/css/fonts.css HTTP/1.1" 200 423
"POST /admin/index/post/ HTTP/1.1" 302 0
"GET /admin/index/post/ HTTP/1.1" 200 5179
"GET /admin/jsi18n/ HTTP/1.1" 200 3223
Not Found: /favicon.ico
"GET /favicon.ico HTTP/1.1" 404 2244
"GET /admin/logout/ HTTP/1.1" 200 1207
Watching for file changes with StatReloader
"GET / HTTP/1.1" 200 7773
Watching for file changes with StatReloader
"GET / HTTP/1.1" 200 7773
Watching for file changes with StatReloader
"GET / HTTP/1.1" 200 7773
"GET / HTTP/1.1" 200 7773
"GET /static/css/normalize.css HTTP/1.1" 304 0
"GET /static/css/style1.css HTTP/1.1" 304 0
"GET /static/fonts/font-awesome-4.3.0/css/font-awesome.min.css HTTP/1.1" 304 0
"GET /static/js/modernizr.custom.js HTTP/1.1" 304 0
"GET /static/js/classie.js HTTP/1.1" 304 0
"GET /static/js/main.js HTTP/1.1" 304 0
"GET /media/default.png HTTP/1.1" 304 0
"GET /media/profile_pics/1.cai.png HTTP/1.1" 304 0
/home/master/PycharmProjects/blog/index/models.py changed, reloading.
Watching for file changes with StatReloader
Watching for file changes with StatReloader
"GET / HTTP/1.1" 200 7773
"GET / HTTP/1.1" 200 7773
"GET /static/css/normalize.css HTTP/1.1" 304 0
"GET /static/css/style1.css HTTP/1.1" 304 0
"GET /static/js/modernizr.custom.js HTTP/1.1" 304 0
"GET /static/fonts/font-awesome-4.3.0/css/font-awesome.min.css HTTP/1.1" 304 0
"GET /static/js/classie.js HTTP/1.1" 304 0
"GET /static/js/main.js HTTP/1.1" 304 0
"GET /media/default.png HTTP/1.1" 304 0
"GET /media/profile_pics/1.cai.png HTTP/1.1" 304 0
"GET / HTTP/1.1" 200 7773
"GET /media/default.png HTTP/1.1" 200 1960
"GET /media/profile_pics/1.cai.png HTTP/1.1" 200 7288
"GET /static/fonts/font-awesome-4.3.0/css/font-awesome.min.css HTTP/1.1" 200 23739
"GET /static/css/style1.css HTTP/1.1" 200 18644
"GET /static/fonts/font-awesome-4.3.0/fonts/fontawesome-webfont.woff2?v=4.3.0 HTTP/1.1" 200 56780
Not Found: /favicon.ico
"GET /favicon.ico HTTP/1.1" 404 2244
"GET /admin HTTP/1.1" 301 0
"GET /admin/ HTTP/1.1" 302 0
"GET /admin/login/?next=/admin/ HTTP/1.1" 200 1819
"GET /static/admin/css/base.css HTTP/1.1" 200 16378
"GET /static/admin/css/login.css HTTP/1.1" 200 1233
"GET /static/admin/css/responsive.css HTTP/1.1" 200 17944
"GET /static/admin/css/fonts.css HTTP/1.1" 200 423
"GET /static/admin/fonts/Roboto-Regular-webfont.woff HTTP/1.1" 200 85876
"GET /static/admin/fonts/Roboto-Light-webfont.woff HTTP/1.1" 200 85692
"POST /admin/login/?next=/admin/ HTTP/1.1" 302 0
"GET /admin/ HTTP/1.1" 200 7157
"GET /static/admin/css/dashboard.css HTTP/1.1" 200 412
"GET /static/admin/img/icon-changelink.svg HTTP/1.1" 200 380
"GET /static/admin/img/icon-deletelink.svg HTTP/1.1" 200 392
"GET /static/admin/img/icon-addlink.svg HTTP/1.1" 200 331
"GET /static/admin/fonts/Roboto-Bold-webfont.woff HTTP/1.1" 200 86184
"GET /admin/index/post/ HTTP/1.1" 200 5059
"GET /static/admin/js/jquery.init.js HTTP/1.1" 200 363
"GET /static/admin/css/changelists.css HTTP/1.1" 200 6170
"GET /static/admin/js/core.js HTTP/1.1" 200 7135
"GET /admin/jsi18n/ HTTP/1.1" 200 3223
"GET /static/admin/js/admin/RelatedObjectLookups.js HTTP/1.1" 200 6918
"GET /static/admin/js/actions.js HTTP/1.1" 200 6538
"GET /static/admin/js/prepopulate.js HTTP/1.1" 200 1530
"GET /static/admin/js/urlify.js HTTP/1.1" 200 8972
"GET /static/admin/js/vendor/jquery/jquery.js HTTP/1.1" 200 271751
"GET /static/admin/js/vendor/xregexp/xregexp.js HTTP/1.1" 200 128820
"GET /static/admin/img/tooltag-add.svg HTTP/1.1" 200 331
"GET /admin/logout/ HTTP/1.1" 200 1207
"GET / HTTP/1.1" 200 7773
"GET /static/css/normalize.css HTTP/1.1" 200 1825
"GET /static/fonts/font-awesome-4.3.0/css/font-awesome.min.css HTTP/1.1" 200 23739
"GET /static/css/style1.css HTTP/1.1" 200 18644
"GET /media/default.png HTTP/1.1" 200 1960
"GET /media/profile_pics/1.cai.png HTTP/1.1" 200 7288
"GET /static/js/modernizr.custom.js HTTP/1.1" 200 8371
"GET /static/js/classie.js HTTP/1.1" 200 1972
"GET /static/js/main.js HTTP/1.1" 200 7139
"GET /static/fonts/font-awesome-4.3.0/fonts/fontawesome-webfont.woff2?v=4.3.0 HTTP/1.1" 200 56780
Watching for file changes with StatReloader
"GET / HTTP/1.1" 200 7773
"GET /static/css/normalize.css HTTP/1.1" 200 1825
"GET /static/fonts/font-awesome-4.3.0/css/font-awesome.min.css HTTP/1.1" 200 8192
"GET / HTTP/1.1" 200 7773
"GET /static/css/style1.css HTTP/1.1" 304 0
"GET /static/fonts/font-awesome-4.3.0/css/font-awesome.min.css HTTP/1.1" 304 0
"GET /static/css/normalize.css HTTP/1.1" 304 0
"GET /static/js/modernizr.custom.js HTTP/1.1" 304 0
"GET /static/js/main.js HTTP/1.1" 304 0
"GET /static/js/classie.js HTTP/1.1" 304 0
"GET /media/default.png HTTP/1.1" 304 0
"GET /media/profile_pics/1.cai.png HTTP/1.1" 304 0
Watching for file changes with StatReloader
"GET / HTTP/1.1" 200 7773
"GET /static/css/normalize.css HTTP/1.1" 200 1825
"GET / HTTP/1.1" 200 7773
"GET /static/css/style1.css HTTP/1.1" 304 0
"GET /static/js/modernizr.custom.js HTTP/1.1" 304 0
"GET /static/fonts/font-awesome-4.3.0/css/font-awesome.min.css HTTP/1.1" 304 0
"GET /static/js/classie.js HTTP/1.1" 304 0
"GET /static/js/main.js HTTP/1.1" 304 0
"GET /static/css/normalize.css HTTP/1.1" 304 0
"GET /media/default.png HTTP/1.1" 304 0
"GET /media/profile_pics/1.cai.png HTTP/1.1" 304 0
Watching for file changes with StatReloader
"GET / HTTP/1.1" 200 7773
/home/master/PycharmProjects/blog/index/models.py changed, reloading.
Watching for file changes with StatReloader
"GET / HTTP/1.1" 200 7773
"GET / HTTP/1.1" 200 7773
"GET /static/css/normalize.css HTTP/1.1" 304 0
"GET /static/css/style1.css HTTP/1.1" 304 0
"GET /static/fonts/font-awesome-4.3.0/css/font-awesome.min.css HTTP/1.1" 304 0
"GET /static/js/modernizr.custom.js HTTP/1.1" 304 0
"GET /static/js/classie.js HTTP/1.1" 304 0
"GET /static/js/main.js HTTP/1.1" 304 0
"GET /media/default.png HTTP/1.1" 304 0
"GET /media/profile_pics/1.cai.png HTTP/1.1" 304 0
/home/master/PycharmProjects/blog/index/models.py changed, reloading.
Watching for file changes with StatReloader
"GET / HTTP/1.1" 200 7773
"GET / HTTP/1.1" 200 7773
"GET /static/fonts/font-awesome-4.3.0/css/font-awesome.min.css HTTP/1.1" 304 0
"GET /static/css/normalize.css HTTP/1.1" 304 0
"GET /static/js/modernizr.custom.js HTTP/1.1" 304 0
"GET /static/css/style1.css HTTP/1.1" 304 0
"GET /static/js/classie.js HTTP/1.1" 304 0
"GET /static/js/main.js HTTP/1.1" 304 0
"GET /media/profile_pics/1.cai.png HTTP/1.1" 304 0
"GET /media/default.png HTTP/1.1" 304 0
Watching for file changes with StatReloader
"GET / HTTP/1.1" 200 7773
"GET /static/css/normalize.css HTTP/1.1" 200 1825
/home/master/PycharmProjects/blog/index/models.py changed, reloading.
Watching for file changes with StatReloader
"GET / HTTP/1.1" 200 7773
"GET /static/css/normalize.css HTTP/1.1" 200 1825
"GET /static/fonts/font-awesome-4.3.0/fonts/fontawesome-webfont.woff2?v=4.3.0 HTTP/1.1" 200 8192
"GET / HTTP/1.1" 200 7773
"GET /static/css/normalize.css HTTP/1.1" 304 0
"GET /static/css/style1.css HTTP/1.1" 304 0
"GET /static/fonts/font-awesome-4.3.0/css/font-awesome.min.css HTTP/1.1" 304 0
"GET /static/js/classie.js HTTP/1.1" 304 0
"GET /static/js/modernizr.custom.js HTTP/1.1" 304 0
"GET /static/js/main.js HTTP/1.1" 304 0
"GET /media/profile_pics/1.cai.png HTTP/1.1" 304 0
"GET /media/default.png HTTP/1.1" 304 0
Watching for file changes with StatReloader
"GET / HTTP/1.1" 200 7773
"GET /static/css/normalize.css HTTP/1.1" 200 1825
"GET /static/fonts/font-awesome-4.3.0/fonts/fontawesome-webfont.woff2?v=4.3.0 HTTP/1.1" 200 8192
Watching for file changes with StatReloader
Watching for file changes with StatReloader
Watching for file changes with StatReloader
"GET / HTTP/1.1" 200 7773
"GET / HTTP/1.1" 200 7773
"GET /static/fonts/font-awesome-4.3.0/css/font-awesome.min.css HTTP/1.1" 304 0
"GET /static/js/modernizr.custom.js HTTP/1.1" 304 0
"GET /static/css/normalize.css HTTP/1.1" 304 0
"GET /static/css/style1.css HTTP/1.1" 304 0
"GET /static/js/classie.js HTTP/1.1" 304 0
"GET /static/js/main.js HTTP/1.1" 304 0
"GET /media/default.png HTTP/1.1" 304 0
"GET /media/profile_pics/1.cai.png HTTP/1.1" 304 0
"GET / HTTP/1.1" 200 7773
"GET /static/css/normalize.css HTTP/1.1" 200 1825
"GET /static/fonts/font-awesome-4.3.0/css/font-awesome.min.css HTTP/1.1" 200 23739
"GET /static/js/classie.js HTTP/1.1" 200 1972
"GET /static/css/style1.css HTTP/1.1" 200 18644
"GET /static/js/modernizr.custom.js HTTP/1.1" 200 8371
"GET /static/js/main.js HTTP/1.1" 200 7139
"GET /media/default.png HTTP/1.1" 200 1960
"GET /media/profile_pics/1.cai.png HTTP/1.1" 200 7288
"GET /static/fonts/font-awesome-4.3.0/fonts/fontawesome-webfont.woff2?v=4.3.0 HTTP/1.1" 200 56780
Not Found: /favicon.ico
"GET /favicon.ico HTTP/1.1" 404 2244
Watching for file changes with StatReloader
"GET / HTTP/1.1" 200 7773
"GET /static/css/normalize.css HTTP/1.1" 200 1825
"GET /static/fonts/font-awesome-4.3.0/fonts/fontawesome-webfont.woff2?v=4.3.0 HTTP/1.1" 200 8192
Watching for file changes with StatReloader
"GET / HTTP/1.1" 200 7773
"GET / HTTP/1.1" 200 7773
"GET /static/css/normalize.css HTTP/1.1" 304 0
"GET /static/fonts/font-awesome-4.3.0/css/font-awesome.min.css HTTP/1.1" 304 0
"GET /static/js/modernizr.custom.js HTTP/1.1" 304 0
"GET /static/css/style1.css HTTP/1.1" 304 0
"GET /static/js/classie.js HTTP/1.1" 304 0
"GET /static/js/main.js HTTP/1.1" 304 0
"GET /media/default.png HTTP/1.1" 304 0
"GET /media/profile_pics/1.cai.png HTTP/1.1" 304 0
"GET / HTTP/1.1" 200 7773
"GET /static/fonts/font-awesome-4.3.0/css/font-awesome.min.css HTTP/1.1" 304 0
"GET /static/css/normalize.css HTTP/1.1" 304 0
"GET /static/js/classie.js HTTP/1.1" 304 0
"GET /static/js/main.js HTTP/1.1" 304 0
"GET /static/css/style1.css HTTP/1.1" 304 0
"GET /static/js/modernizr.custom.js HTTP/1.1" 304 0
"GET /media/profile_pics/1.cai.png HTTP/1.1" 304 0
"GET /media/default.png HTTP/1.1" 304 0
"GET /admin/ HTTP/1.1" 302 0
"GET /admin/login/?next=/admin/ HTTP/1.1" 200 1819
"GET /static/admin/css/login.css HTTP/1.1" 200 1233
"GET /static/admin/css/base.css HTTP/1.1" 200 16378
"GET /static/admin/css/responsive.css HTTP/1.1" 200 17944
"GET /static/admin/css/fonts.css HTTP/1.1" 200 423
"GET /static/admin/fonts/Roboto-Regular-webfont.woff HTTP/1.1" 200 85876
"GET /static/admin/fonts/Roboto-Light-webfont.woff HTTP/1.1" 200 85692
"POST /admin/login/?next=/admin/ HTTP/1.1" 302 0
"GET /admin/ HTTP/1.1" 200 7157
"GET /static/admin/css/dashboard.css HTTP/1.1" 200 412
"GET /static/admin/img/icon-addlink.svg HTTP/1.1" 200 331
"GET /static/admin/img/icon-changelink.svg HTTP/1.1" 200 380
"GET /static/admin/img/icon-deletelink.svg HTTP/1.1" 200 392
"GET /static/admin/fonts/Roboto-Bold-webfont.woff HTTP/1.1" 200 86184
"GET /admin/index/post/ HTTP/1.1" 200 5059
"GET /static/admin/js/core.js HTTP/1.1" 200 7135
"GET /static/admin/js/admin/RelatedObjectLookups.js HTTP/1.1" 200 6918
"GET /static/admin/css/changelists.css HTTP/1.1" 200 6170
"GET /static/admin/js/jquery.init.js HTTP/1.1" 200 363
"GET /admin/jsi18n/ HTTP/1.1" 200 3223
"GET /static/admin/js/prepopulate.js HTTP/1.1" 200 1530
"GET /static/admin/js/urlify.js HTTP/1.1" 200 8972
"GET /static/admin/js/actions.js HTTP/1.1" 200 6538
"GET /static/admin/js/vendor/xregexp/xregexp.js HTTP/1.1" 200 128820
"GET /static/admin/js/vendor/jquery/jquery.js HTTP/1.1" 200 271751
"GET /static/admin/img/tooltag-add.svg HTTP/1.1" 200 331
"GET /admin/logout/ HTTP/1.1" 200 1207
"GET / HTTP/1.1" 200 7773
Watching for file changes with StatReloader
"GET / HTTP/1.1" 200 7773
"GET / HTTP/1.1" 200 7773
"GET /static/css/normalize.css HTTP/1.1" 304 0
"GET /static/fonts/font-awesome-4.3.0/css/font-awesome.min.css HTTP/1.1" 304 0
"GET /static/js/classie.js HTTP/1.1" 304 0
"GET /static/css/style1.css HTTP/1.1" 304 0
"GET /static/js/main.js HTTP/1.1" 304 0
"GET /static/js/modernizr.custom.js HTTP/1.1" 304 0
"GET /media/profile_pics/1.cai.png HTTP/1.1" 304 0
"GET /media/default.png HTTP/1.1" 304 0
Watching for file changes with StatReloader
"GET / HTTP/1.1" 200 7773
"GET / HTTP/1.1" 200 7773
/home/master/PycharmProjects/blog/index/models.py changed, reloading.
Watching for file changes with StatReloader
Watching for file changes with StatReloader
"GET / HTTP/1.1" 200 7773
"GET /media/default.png HTTP/1.1" 304 0
"GET /media/profile_pics/1.cai.png HTTP/1.1" 304 0
"GET /static/css/style1.css HTTP/1.1" 304 0
Not Found: /favicon.ico
"GET /favicon.ico HTTP/1.1" 404 2244
Watching for file changes with StatReloader
"GET / HTTP/1.1" 200 7773
"GET /static/css/style1.css HTTP/1.1" 304 0
"GET /media/default.png HTTP/1.1" 304 0
"GET /media/profile_pics/1.cai.png HTTP/1.1" 304 0
Watching for file changes with StatReloader
"GET / HTTP/1.1" 200 7773
"GET /static/css/normalize.css HTTP/1.1" 200 1825
Watching for file changes with StatReloader
"GET / HTTP/1.1" 200 7773
/home/master/PycharmProjects/blog/index/models.py changed, reloading.
Watching for file changes with StatReloader
"GET / HTTP/1.1" 200 7773
"GET /static/css/normalize.css HTTP/1.1" 200 1825
"GET /static/fonts/font-awesome-4.3.0/fonts/fontawesome-webfont.woff2?v=4.3.0 HTTP/1.1" 200 8192
Watching for file changes with StatReloader
"GET / HTTP/1.1" 200 7773
"GET /static/css/normalize.css HTTP/1.1" 200 1825
"GET /static/fonts/font-awesome-4.3.0/fonts/fontawesome-webfont.woff2?v=4.3.0 HTTP/1.1" 200 8192
/home/master/PycharmProjects/blog/index/models.py changed, reloading.
Watching for file changes with StatReloader
Watching for file changes with StatReloader
"GET / HTTP/1.1" 200 7773
"GET /static/css/normalize.css HTTP/1.1" 200 1825
"GET /static/fonts/font-awesome-4.3.0/fonts/fontawesome-webfont.woff2?v=4.3.0 HTTP/1.1" 200 8192
Watching for file changes with StatReloader
"GET / HTTP/1.1" 200 7773
"GET /static/css/normalize.css HTTP/1.1" 200 1825
"GET /static/fonts/font-awesome-4.3.0/fonts/fontawesome-webfont.woff2?v=4.3.0 HTTP/1.1" 200 8192
Watching for file changes with StatReloader
"GET / HTTP/1.1" 200 7773
"GET /static/css/normalize.css HTTP/1.1" 200 1825
"GET /static/fonts/font-awesome-4.3.0/fonts/fontawesome-webfont.woff2?v=4.3.0 HTTP/1.1" 200 8192
Watching for file changes with StatReloader
"GET / HTTP/1.1" 200 7773
"GET /static/css/normalize.css HTTP/1.1" 200 1825
Watching for file changes with StatReloader
"GET / HTTP/1.1" 200 7773
"GET /static/css/normalize.css HTTP/1.1" 200 1825
"GET /static/fonts/font-awesome-4.3.0/fonts/fontawesome-webfont.woff2?v=4.3.0 HTTP/1.1" 200 8192
Watching for file changes with StatReloader
"GET / HTTP/1.1" 200 7773
"GET /static/css/normalize.css HTTP/1.1" 200 1825
"GET /static/fonts/font-awesome-4.3.0/fonts/fontawesome-webfont.woff2?v=4.3.0 HTTP/1.1" 200 8192
Watching for file changes with StatReloader
"GET / HTTP/1.1" 200 7773
"GET /static/css/normalize.css HTTP/1.1" 200 1825
/home/master/PycharmProjects/blog/index/models.py changed, reloading.
Watching for file changes with StatReloader
Watching for file changes with StatReloader
"GET / HTTP/1.1" 200 7773
"GET /static/css/normalize.css HTTP/1.1" 200 1825
Watching for file changes with StatReloader
"GET / HTTP/1.1" 200 7773
"GET /static/css/normalize.css HTTP/1.1" 200 1825
"GET /static/fonts/font-awesome-4.3.0/fonts/fontawesome-webfont.woff2?v=4.3.0 HTTP/1.1" 200 8192
/home/master/PycharmProjects/blog/index/models.py changed, reloading.
Watching for file changes with StatReloader
/home/master/PycharmProjects/blog/index/models.py changed, reloading.
Watching for file changes with StatReloader
Watching for file changes with StatReloader
"GET / HTTP/1.1" 200 7773
"GET /static/css/normalize.css HTTP/1.1" 200 1825
"GET /static/fonts/font-awesome-4.3.0/fonts/fontawesome-webfont.woff2?v=4.3.0 HTTP/1.1" 200 8192
"GET / HTTP/1.1" 200 7773
"GET /static/css/normalize.css HTTP/1.1" 304 0
"GET /static/js/classie.js HTTP/1.1" 304 0
"GET /static/fonts/font-awesome-4.3.0/css/font-awesome.min.css HTTP/1.1" 304 0
"GET /static/js/modernizr.custom.js HTTP/1.1" 304 0
"GET /static/js/main.js HTTP/1.1" 304 0
"GET /static/css/style1.css HTTP/1.1" 304 0
"GET /media/default.png HTTP/1.1" 304 0
"GET /media/profile_pics/1.cai.png HTTP/1.1" 304 0
Watching for file changes with StatReloader
"GET / HTTP/1.1" 200 7773
"GET /static/css/normalize.css HTTP/1.1" 200 1825
"GET /static/fonts/font-awesome-4.3.0/fonts/fontawesome-webfont.woff2?v=4.3.0 HTTP/1.1" 200 8192
Watching for file changes with StatReloader
"GET / HTTP/1.1" 200 7773
"GET /static/css/normalize.css HTTP/1.1" 200 1825
"GET / HTTP/1.1" 200 7773
"GET /static/css/normalize.css HTTP/1.1" 304 0
"GET /static/fonts/font-awesome-4.3.0/css/font-awesome.min.css HTTP/1.1" 304 0
"GET /static/css/style1.css HTTP/1.1" 304 0
"GET /static/js/modernizr.custom.js HTTP/1.1" 304 0
"GET /static/js/classie.js HTTP/1.1" 304 0
"GET /static/js/main.js HTTP/1.1" 304 0
"GET /media/profile_pics/1.cai.png HTTP/1.1" 304 0
"GET /media/default.png HTTP/1.1" 304 0
Watching for file changes with StatReloader
"GET / HTTP/1.1" 200 7773
"GET /static/css/style1.css HTTP/1.1" 304 0
"GET /static/css/normalize.css HTTP/1.1" 200 1825
"GET /media/default.png HTTP/1.1" 200 1960
"GET /media/profile_pics/1.cai.png HTTP/1.1" 304 0
